<?xml version="1.0"?>
<robot xmlns:xacro="http://www.ros.org/wiki/xacro">

    <xacro:include filename='inertial_macros.xacro'></xacro:include>

    <material name="white">
        <color rgba="1 1 1 1"></color>
    </material>

    <material name="black">
        <color rgba="0 0 0 1"></color>
    </material>

    <material name="purple">
        <color rgba="0.6 0.06 0.7 1"></color>
    </material>

    <material name="magenta">
        <color rgba="0.75 0 0.4 1"></color>
    </material>

    <!-- BASE LINK-->

    <link name="base_link">

    </link>

    <!-- CHASSIS LINK-->

    <joint name="chassis_joint" type="fixed">
        <parent link="base_link"></parent>
        <child link="chassis"></child>
        <origin xyz="-0.15 0 0"></origin>
    </joint>

    <link name="chassis">
        <visual>
            <origin xyz="0.15 0 0.06"></origin>
            <geometry>
                <box size="0.3 0.2 0.12"></box>
            </geometry>
            <material name="purple"></material>
        </visual>
        <collision>
            <origin xyz="0.15 0 0.06"></origin>
            <geometry>
                <box size="0.3 0.2 0.12"></box>
            </geometry>
        </collision>

        <xacro:inertial_box mass="0.5" x="0.3" y="0.2" z="0.12">
            <origin xyz="0.15 0 0.06" rpy="0 0 0"></origin>
        </xacro:inertial_box>
    </link>

    <gazebo reference="chassis">
        <material>Gazebo/Purple</material>
    </gazebo>

    <!-- BACK LEFT WHEEL LINK-->

    <joint name="back_left_wheel_joint" type="continuous">
        <parent link="base_link"></parent>
        <child link="back_left_wheel"></child>
        <origin xyz="-0.1 0.1 0" rpy="-${pi/2} 0 0"></origin>
        <axis xyz="0 0 1"></axis>
    </joint>

    <link name="back_left_wheel">
        <visual>
            
            <geometry>
                <cylinder radius="0.05" length="0.04"></cylinder>
            </geometry>
            <material name="black"></material>
        </visual>
        <collision>
            <geometry>
                <cylinder radius="0.05" length="0.04"></cylinder>
            </geometry>
        </collision>
        <xacro:inertial_cylinder mass="0.1" length="0.04" radius="0.05">
            <origin xyz="0 0 0" rpy="0 0 0"></origin>
        </xacro:inertial_cylinder>
    </link>

    <gazebo reference="back_left_wheel">
        <material>Gazebo/Black</material>
    </gazebo>

    <!-- BACK RIGHT WHEEL LINK-->

    <joint name="back_right_wheel_joint" type="continuous">
        <parent link="base_link"></parent>
        <child link="back_right_wheel"></child>
        <origin xyz="-0.1 -0.1 0" rpy="${pi/2} 0 0"></origin>
        <axis xyz="0 0 -1"></axis>
    </joint>

    <link name="back_right_wheel">
        <visual>
            
            <geometry>
                <cylinder radius="0.05" length="0.04"></cylinder>
            </geometry>
            <material name="black"></material>
        </visual>

        <collision>
            <geometry>
                <cylinder radius="0.05" length="0.04"></cylinder>
            </geometry>
        </collision>

        <xacro:inertial_cylinder mass="0.1" length="0.04" radius="0.05">
            <origin xyz="0 0 0" rpy="0 0 0"></origin>
        </xacro:inertial_cylinder>
    </link>

    <gazebo reference="back_right_wheel">
        <material>Gazebo/Black</material>
    </gazebo>

    <!-- FRONT LEFT WHEEL LINK-->

    <joint name="front_left_wheel_joint" type="continuous">
        <parent link="base_link"></parent>
        <child link="front_left_wheel"></child>
        <origin xyz="0.1 0.1 0" rpy="-${pi/2} 0 0"></origin>
        <axis xyz="0 0 1"></axis>
    </joint>

    <link name="front_left_wheel">
        <visual>
            
            <geometry>
                <cylinder radius="0.05" length="0.04"></cylinder>
            </geometry>
            <material name="black"></material>
        </visual>

        <collision>
            <geometry>
                <cylinder radius="0.05" length="0.04"></cylinder>
            </geometry>
        </collision>

        <xacro:inertial_cylinder mass="0.1" length="0.04" radius="0.05">
            <origin xyz="0 0 0" rpy="0 0 0"></origin>
        </xacro:inertial_cylinder>
    </link>

    <gazebo reference="front_left_wheel">
        <material>Gazebo/Black</material>
    </gazebo>

    <!-- FRONT RIGHT WHEEL LINK-->

    <joint name="front_right_wheel_joint" type="continuous">
        <parent link="base_link"></parent>
        <child link="front_right_wheel"></child>
        <origin xyz="0.1 -0.1 0" rpy="${pi/2} 0 0"></origin>
        <axis xyz="0 0 -1"></axis>
    </joint>

    <link name="front_right_wheel">
        <visual>
            
            <geometry>
                <cylinder radius="0.05" length="0.04"></cylinder>
            </geometry>
            <material name="black"></material>
        </visual>

        <collision>
            <geometry>
                <cylinder radius="0.05" length="0.04"></cylinder>
            </geometry>
        </collision>

        <xacro:inertial_cylinder mass="0.1" length="0.04" radius="0.05">
            <origin xyz="0 0 0" rpy="0 0 0"></origin>
        </xacro:inertial_cylinder>
    </link>

    <gazebo reference="front_right_wheel">
        <material>Gazebo/Black</material>
    </gazebo>

</robot>